[02/Jul/2015 02:55:48] DEBUG [django.db.backends:89] (0.001) QUERY = "\n            SELECT name, type FROM sqlite_master\n            WHERE type in ('table', 'view') AND NOT name='sqlite_sequence'\n            ORDER BY name" - PARAMS = (); args=None
[02/Jul/2015 02:55:48] DEBUG [django.db.backends:89] (0.000) QUERY = u'BEGIN' - PARAMS = (); args=None
[02/Jul/2015 02:55:48] DEBUG [django.db.backends.schema:102] CREATE TABLE "django_migrations" ("id" integer NOT NULL PRIMARY KEY AUTOINCREMENT, "app" varchar(255) NOT NULL, "name" varchar(255) NOT NULL, "applied" datetime NOT NULL); (params None)
[02/Jul/2015 02:55:48] DEBUG [django.db.backends:89] (0.025) QUERY = u'CREATE TABLE "django_migrations" ("id" integer NOT NULL PRIMARY KEY AUTOINCREMENT, "app" varchar(255) NOT NULL, "name" varchar(255) NOT NULL, "applied" datetime NOT NULL)' - PARAMS = (); args=None
[02/Jul/2015 02:55:48] DEBUG [django.db.backends:89] (0.000) QUERY = u'SELECT "django_migrations"."app", "django_migrations"."name" FROM "django_migrations"' - PARAMS = (); args=()
[02/Jul/2015 02:55:58] WARNING [django.request:170] Not Found: /
[02/Jul/2015 02:55:58] WARNING [django.request:170] Not Found: /favicon.ico
[02/Jul/2015 02:55:58] WARNING [django.request:170] Not Found: /favicon.ico
[02/Jul/2015 02:56:09] ERROR [django.request:256] Internal Server Error: /new-level/
Traceback (most recent call last):
  File "/usr/local/lib/python2.7/dist-packages/django/core/handlers/base.py", line 119, in get_response
    resolver_match = resolver.resolve(request.path_info)
  File "/usr/local/lib/python2.7/dist-packages/django/core/urlresolvers.py", line 368, in resolve
    sub_match = pattern.resolve(new_path)
  File "/usr/local/lib/python2.7/dist-packages/django/core/urlresolvers.py", line 240, in resolve
    return ResolverMatch(self.callback, args, kwargs, self.name)
  File "/usr/local/lib/python2.7/dist-packages/django/core/urlresolvers.py", line 247, in callback
    self._callback = get_callable(self._callback_str)
  File "/usr/local/lib/python2.7/dist-packages/django/utils/lru_cache.py", line 101, in wrapper
    result = user_function(*args, **kwds)
  File "/usr/local/lib/python2.7/dist-packages/django/core/urlresolvers.py", line 112, in get_callable
    if submod and not module_has_submodule(import_module(parentmod), submod):
  File "/usr/lib/python2.7/importlib/__init__.py", line 37, in import_module
    __import__(name)
ImportError: No module named admin
[02/Jul/2015 02:57:50] ERROR [django.request:256] Internal Server Error: /new-level/
Traceback (most recent call last):
  File "/usr/local/lib/python2.7/dist-packages/django/core/handlers/base.py", line 119, in get_response
    resolver_match = resolver.resolve(request.path_info)
  File "/usr/local/lib/python2.7/dist-packages/django/core/urlresolvers.py", line 368, in resolve
    sub_match = pattern.resolve(new_path)
  File "/usr/local/lib/python2.7/dist-packages/django/core/urlresolvers.py", line 240, in resolve
    return ResolverMatch(self.callback, args, kwargs, self.name)
  File "/usr/local/lib/python2.7/dist-packages/django/core/urlresolvers.py", line 247, in callback
    self._callback = get_callable(self._callback_str)
  File "/usr/local/lib/python2.7/dist-packages/django/utils/lru_cache.py", line 101, in wrapper
    result = user_function(*args, **kwds)
  File "/usr/local/lib/python2.7/dist-packages/django/core/urlresolvers.py", line 112, in get_callable
    if submod and not module_has_submodule(import_module(parentmod), submod):
  File "/usr/lib/python2.7/importlib/__init__.py", line 37, in import_module
    __import__(name)
ImportError: No module named admin
[02/Jul/2015 02:58:41] DEBUG [django.db.backends:89] (0.000) QUERY = "\n            SELECT name, type FROM sqlite_master\n            WHERE type in ('table', 'view') AND NOT name='sqlite_sequence'\n            ORDER BY name" - PARAMS = (); args=None
[02/Jul/2015 02:58:41] DEBUG [django.db.backends:89] (0.000) QUERY = u'SELECT "django_migrations"."app", "django_migrations"."name" FROM "django_migrations"' - PARAMS = (); args=()
[02/Jul/2015 03:03:45] DEBUG [django.db.backends:89] (0.001) QUERY = "\n            SELECT name, type FROM sqlite_master\n            WHERE type in ('table', 'view') AND NOT name='sqlite_sequence'\n            ORDER BY name" - PARAMS = (); args=None
[02/Jul/2015 03:03:45] DEBUG [django.db.backends:89] (0.000) QUERY = u'SELECT "django_migrations"."app", "django_migrations"."name" FROM "django_migrations"' - PARAMS = (); args=()
[02/Jul/2015 03:03:50] DEBUG [django.db.backends:89] (0.000) QUERY = "\n            SELECT name, type FROM sqlite_master\n            WHERE type in ('table', 'view') AND NOT name='sqlite_sequence'\n            ORDER BY name" - PARAMS = (); args=None
[02/Jul/2015 03:03:50] DEBUG [django.db.backends:89] (0.000) QUERY = u'SELECT "django_migrations"."app", "django_migrations"."name" FROM "django_migrations"' - PARAMS = (); args=()
[02/Jul/2015 03:03:54] DEBUG [django.db.backends:89] (0.001) QUERY = "\n            SELECT name, type FROM sqlite_master\n            WHERE type in ('table', 'view') AND NOT name='sqlite_sequence'\n            ORDER BY name" - PARAMS = (); args=None
[02/Jul/2015 03:03:54] DEBUG [django.db.backends:89] (0.000) QUERY = u'SELECT "django_migrations"."app", "django_migrations"."name" FROM "django_migrations"' - PARAMS = (); args=()
[02/Jul/2015 03:04:18] DEBUG [django.db.backends:89] (0.000) QUERY = "\n            SELECT name, type FROM sqlite_master\n            WHERE type in ('table', 'view') AND NOT name='sqlite_sequence'\n            ORDER BY name" - PARAMS = (); args=None
[02/Jul/2015 03:04:18] DEBUG [django.db.backends:89] (0.000) QUERY = u'SELECT "django_migrations"."app", "django_migrations"."name" FROM "django_migrations"' - PARAMS = (); args=()
[02/Jul/2015 03:05:27] DEBUG [django.db.backends:89] (0.001) QUERY = "\n            SELECT name, type FROM sqlite_master\n            WHERE type in ('table', 'view') AND NOT name='sqlite_sequence'\n            ORDER BY name" - PARAMS = (); args=None
[02/Jul/2015 03:05:27] DEBUG [django.db.backends:89] (0.000) QUERY = u'SELECT "django_migrations"."app", "django_migrations"."name" FROM "django_migrations"' - PARAMS = (); args=()
[02/Jul/2015 03:06:19] DEBUG [django.db.backends:89] (0.001) QUERY = "\n            SELECT name, type FROM sqlite_master\n            WHERE type in ('table', 'view') AND NOT name='sqlite_sequence'\n            ORDER BY name" - PARAMS = (); args=None
[02/Jul/2015 03:06:19] DEBUG [django.db.backends:89] (0.000) QUERY = u'SELECT "django_migrations"."app", "django_migrations"."name" FROM "django_migrations"' - PARAMS = (); args=()
[02/Jul/2015 03:06:20] DEBUG [django.db.backends:89] (0.000) QUERY = "\n            SELECT name, type FROM sqlite_master\n            WHERE type in ('table', 'view') AND NOT name='sqlite_sequence'\n            ORDER BY name" - PARAMS = (); args=None
[02/Jul/2015 03:06:20] DEBUG [django.db.backends:89] (0.000) QUERY = u'SELECT "django_migrations"."app", "django_migrations"."name" FROM "django_migrations"' - PARAMS = (); args=()
[02/Jul/2015 03:31:43] DEBUG [django.db.backends:89] (0.000) QUERY = "\n            SELECT name, type FROM sqlite_master\n            WHERE type in ('table', 'view') AND NOT name='sqlite_sequence'\n            ORDER BY name" - PARAMS = (); args=None
[02/Jul/2015 03:31:43] DEBUG [django.db.backends:89] (0.000) QUERY = u'SELECT "django_migrations"."app", "django_migrations"."name" FROM "django_migrations"' - PARAMS = (); args=()
[02/Jul/2015 03:31:48] ERROR [django.request:256] Internal Server Error: /new-level/
Traceback (most recent call last):
  File "/usr/local/lib/python2.7/dist-packages/django/core/handlers/base.py", line 119, in get_response
    resolver_match = resolver.resolve(request.path_info)
  File "/usr/local/lib/python2.7/dist-packages/django/core/urlresolvers.py", line 368, in resolve
    sub_match = pattern.resolve(new_path)
  File "/usr/local/lib/python2.7/dist-packages/django/core/urlresolvers.py", line 240, in resolve
    return ResolverMatch(self.callback, args, kwargs, self.name)
  File "/usr/local/lib/python2.7/dist-packages/django/core/urlresolvers.py", line 247, in callback
    self._callback = get_callable(self._callback_str)
  File "/usr/local/lib/python2.7/dist-packages/django/utils/lru_cache.py", line 101, in wrapper
    result = user_function(*args, **kwds)
  File "/usr/local/lib/python2.7/dist-packages/django/core/urlresolvers.py", line 106, in get_callable
    mod = import_module(mod_name)
  File "/usr/lib/python2.7/importlib/__init__.py", line 37, in import_module
    __import__(name)
  File "/home/muzavan/Documents/Proyek/kosong/level/views.py", line 18
    answer = form.cleaned_data['answer']
    ^
IndentationError: unexpected indent
[02/Jul/2015 03:32:07] ERROR [django.request:256] Internal Server Error: /new-level/
Traceback (most recent call last):
  File "/usr/local/lib/python2.7/dist-packages/django/core/handlers/base.py", line 119, in get_response
    resolver_match = resolver.resolve(request.path_info)
  File "/usr/local/lib/python2.7/dist-packages/django/core/urlresolvers.py", line 368, in resolve
    sub_match = pattern.resolve(new_path)
  File "/usr/local/lib/python2.7/dist-packages/django/core/urlresolvers.py", line 240, in resolve
    return ResolverMatch(self.callback, args, kwargs, self.name)
  File "/usr/local/lib/python2.7/dist-packages/django/core/urlresolvers.py", line 247, in callback
    self._callback = get_callable(self._callback_str)
  File "/usr/local/lib/python2.7/dist-packages/django/utils/lru_cache.py", line 101, in wrapper
    result = user_function(*args, **kwds)
  File "/usr/local/lib/python2.7/dist-packages/django/core/urlresolvers.py", line 106, in get_callable
    mod = import_module(mod_name)
  File "/usr/lib/python2.7/importlib/__init__.py", line 37, in import_module
    __import__(name)
  File "/home/muzavan/Documents/Proyek/kosong/level/views.py", line 18
    answer = form.cleaned_data['answer']
    ^
IndentationError: unexpected indent
[02/Jul/2015 03:32:18] ERROR [django.request:256] Internal Server Error: /new-level/
Traceback (most recent call last):
  File "/usr/local/lib/python2.7/dist-packages/django/core/handlers/base.py", line 119, in get_response
    resolver_match = resolver.resolve(request.path_info)
  File "/usr/local/lib/python2.7/dist-packages/django/core/urlresolvers.py", line 368, in resolve
    sub_match = pattern.resolve(new_path)
  File "/usr/local/lib/python2.7/dist-packages/django/core/urlresolvers.py", line 240, in resolve
    return ResolverMatch(self.callback, args, kwargs, self.name)
  File "/usr/local/lib/python2.7/dist-packages/django/core/urlresolvers.py", line 247, in callback
    self._callback = get_callable(self._callback_str)
  File "/usr/local/lib/python2.7/dist-packages/django/utils/lru_cache.py", line 101, in wrapper
    result = user_function(*args, **kwds)
  File "/usr/local/lib/python2.7/dist-packages/django/core/urlresolvers.py", line 106, in get_callable
    mod = import_module(mod_name)
  File "/usr/lib/python2.7/importlib/__init__.py", line 37, in import_module
    __import__(name)
  File "/home/muzavan/Documents/Proyek/kosong/level/views.py", line 18
    answer = form.cleaned_data['answer']
    ^
IndentationError: unexpected indent
[02/Jul/2015 03:32:20] ERROR [django.request:256] Internal Server Error: /new-level/
Traceback (most recent call last):
  File "/usr/local/lib/python2.7/dist-packages/django/core/handlers/base.py", line 119, in get_response
    resolver_match = resolver.resolve(request.path_info)
  File "/usr/local/lib/python2.7/dist-packages/django/core/urlresolvers.py", line 368, in resolve
    sub_match = pattern.resolve(new_path)
  File "/usr/local/lib/python2.7/dist-packages/django/core/urlresolvers.py", line 240, in resolve
    return ResolverMatch(self.callback, args, kwargs, self.name)
  File "/usr/local/lib/python2.7/dist-packages/django/core/urlresolvers.py", line 247, in callback
    self._callback = get_callable(self._callback_str)
  File "/usr/local/lib/python2.7/dist-packages/django/utils/lru_cache.py", line 101, in wrapper
    result = user_function(*args, **kwds)
  File "/usr/local/lib/python2.7/dist-packages/django/core/urlresolvers.py", line 106, in get_callable
    mod = import_module(mod_name)
  File "/usr/lib/python2.7/importlib/__init__.py", line 37, in import_module
    __import__(name)
  File "/home/muzavan/Documents/Proyek/kosong/level/views.py", line 18
    answer = form.cleaned_data['answer']
    ^
IndentationError: unexpected indent
[02/Jul/2015 03:33:09] ERROR [django.request:256] Internal Server Error: /new-level/
Traceback (most recent call last):
  File "/usr/local/lib/python2.7/dist-packages/django/core/handlers/base.py", line 119, in get_response
    resolver_match = resolver.resolve(request.path_info)
  File "/usr/local/lib/python2.7/dist-packages/django/core/urlresolvers.py", line 368, in resolve
    sub_match = pattern.resolve(new_path)
  File "/usr/local/lib/python2.7/dist-packages/django/core/urlresolvers.py", line 240, in resolve
    return ResolverMatch(self.callback, args, kwargs, self.name)
  File "/usr/local/lib/python2.7/dist-packages/django/core/urlresolvers.py", line 247, in callback
    self._callback = get_callable(self._callback_str)
  File "/usr/local/lib/python2.7/dist-packages/django/utils/lru_cache.py", line 101, in wrapper
    result = user_function(*args, **kwds)
  File "/usr/local/lib/python2.7/dist-packages/django/core/urlresolvers.py", line 106, in get_callable
    mod = import_module(mod_name)
  File "/usr/lib/python2.7/importlib/__init__.py", line 37, in import_module
    __import__(name)
  File "/home/muzavan/Documents/Proyek/kosong/level/views.py", line 18
    answer = form.cleaned_data['answer']
    ^
IndentationError: unexpected indent
[02/Jul/2015 03:33:50] ERROR [django.request:256] Internal Server Error: /new-level/
Traceback (most recent call last):
  File "/usr/local/lib/python2.7/dist-packages/django/core/handlers/base.py", line 119, in get_response
    resolver_match = resolver.resolve(request.path_info)
  File "/usr/local/lib/python2.7/dist-packages/django/core/urlresolvers.py", line 368, in resolve
    sub_match = pattern.resolve(new_path)
  File "/usr/local/lib/python2.7/dist-packages/django/core/urlresolvers.py", line 240, in resolve
    return ResolverMatch(self.callback, args, kwargs, self.name)
  File "/usr/local/lib/python2.7/dist-packages/django/core/urlresolvers.py", line 247, in callback
    self._callback = get_callable(self._callback_str)
  File "/usr/local/lib/python2.7/dist-packages/django/utils/lru_cache.py", line 101, in wrapper
    result = user_function(*args, **kwds)
  File "/usr/local/lib/python2.7/dist-packages/django/core/urlresolvers.py", line 106, in get_callable
    mod = import_module(mod_name)
  File "/usr/lib/python2.7/importlib/__init__.py", line 37, in import_module
    __import__(name)
  File "/home/muzavan/Documents/Proyek/kosong/level/views.py", line 18
    answer = form.cleaned_data['answer']
    ^
IndentationError: unexpected indent
[02/Jul/2015 03:33:53] ERROR [django.request:256] Internal Server Error: /new-level/
Traceback (most recent call last):
  File "/usr/local/lib/python2.7/dist-packages/django/core/handlers/base.py", line 119, in get_response
    resolver_match = resolver.resolve(request.path_info)
  File "/usr/local/lib/python2.7/dist-packages/django/core/urlresolvers.py", line 368, in resolve
    sub_match = pattern.resolve(new_path)
  File "/usr/local/lib/python2.7/dist-packages/django/core/urlresolvers.py", line 240, in resolve
    return ResolverMatch(self.callback, args, kwargs, self.name)
  File "/usr/local/lib/python2.7/dist-packages/django/core/urlresolvers.py", line 247, in callback
    self._callback = get_callable(self._callback_str)
  File "/usr/local/lib/python2.7/dist-packages/django/utils/lru_cache.py", line 101, in wrapper
    result = user_function(*args, **kwds)
  File "/usr/local/lib/python2.7/dist-packages/django/core/urlresolvers.py", line 106, in get_callable
    mod = import_module(mod_name)
  File "/usr/lib/python2.7/importlib/__init__.py", line 37, in import_module
    __import__(name)
  File "/home/muzavan/Documents/Proyek/kosong/level/views.py", line 18
    answer = form.cleaned_data['answer']
    ^
IndentationError: unexpected indent
[02/Jul/2015 04:01:44] DEBUG [django.db.backends:89] (0.001) QUERY = "\n            SELECT name, type FROM sqlite_master\n            WHERE type in ('table', 'view') AND NOT name='sqlite_sequence'\n            ORDER BY name" - PARAMS = (); args=None
[02/Jul/2015 04:01:44] DEBUG [django.db.backends:89] (0.000) QUERY = u'SELECT "django_migrations"."app", "django_migrations"."name" FROM "django_migrations"' - PARAMS = (); args=()
[02/Jul/2015 04:05:04] ERROR [django.request:256] Internal Server Error: /new-level/settings/
Traceback (most recent call last):
  File "/usr/local/lib/python2.7/dist-packages/django/core/handlers/base.py", line 132, in get_response
    response = wrapped_callback(request, *callback_args, **callback_kwargs)
  File "/home/muzavan/Documents/Proyek/kosong/level/views.py", line 17, in newLevel
    image = uploadingFile(form.cleaned_data['image'])
  File "/home/muzavan/Documents/Proyek/kosong/level/views.py", line 30, in uploadingFile
    with open(name, 'wb+') as destination:
IOError: [Errno 2] No such file or directory: 'local_media/level/04:05:04.385819_.png'
[02/Jul/2015 04:05:53] ERROR [django.request:256] Internal Server Error: /new-level/settings/
Traceback (most recent call last):
  File "/usr/local/lib/python2.7/dist-packages/django/core/handlers/base.py", line 132, in get_response
    response = wrapped_callback(request, *callback_args, **callback_kwargs)
  File "/home/muzavan/Documents/Proyek/kosong/level/views.py", line 22, in newLevel
    util.newLevel(image,answer,hint,name,linkProfile)
  File "/home/muzavan/Documents/Proyek/kosong/level/models.py", line 27, in newLevel
    cnx.close()
UnboundLocalError: local variable 'cnx' referenced before assignment
[02/Jul/2015 04:21:21] ERROR [django.request:256] Internal Server Error: /new-level/settings/
Traceback (most recent call last):
  File "/usr/local/lib/python2.7/dist-packages/django/core/handlers/base.py", line 132, in get_response
    response = wrapped_callback(request, *callback_args, **callback_kwargs)
  File "/home/muzavan/Documents/Proyek/kosong/level/views.py", line 22, in newLevel
    util.newLevel(image,answer,hint,name,linkProfile)
  File "/home/muzavan/Documents/Proyek/kosong/level/models.py", line 27, in newLevel
    cnx.close()
UnboundLocalError: local variable 'cnx' referenced before assignment
[02/Jul/2015 04:31:30] ERROR [django.request:256] Internal Server Error: /new-level/settings/settings/
Traceback (most recent call last):
  File "/usr/local/lib/python2.7/dist-packages/django/core/handlers/base.py", line 132, in get_response
    response = wrapped_callback(request, *callback_args, **callback_kwargs)
  File "/home/muzavan/Documents/Proyek/kosong/level/views.py", line 22, in newLevel
    util.newLevel(image,answer,hint,name,linkProfile)
  File "/home/muzavan/Documents/Proyek/kosong/level/models.py", line 27, in newLevel
    cnx.close()
UnboundLocalError: local variable 'cnx' referenced before assignment
[02/Jul/2015 04:31:48] DEBUG [django.db.backends:89] (0.000) QUERY = "\n            SELECT name, type FROM sqlite_master\n            WHERE type in ('table', 'view') AND NOT name='sqlite_sequence'\n            ORDER BY name" - PARAMS = (); args=None
[02/Jul/2015 04:31:48] DEBUG [django.db.backends:89] (0.000) QUERY = u'SELECT "django_migrations"."app", "django_migrations"."name" FROM "django_migrations"' - PARAMS = (); args=()
[02/Jul/2015 04:31:52] ERROR [django.request:256] Internal Server Error: /new-level/settings/settings/
Traceback (most recent call last):
  File "/usr/local/lib/python2.7/dist-packages/django/core/handlers/base.py", line 132, in get_response
    response = wrapped_callback(request, *callback_args, **callback_kwargs)
  File "/home/muzavan/Documents/Proyek/kosong/level/views.py", line 22, in newLevel
    util.newLevel(image,answer,hint,name,linkProfile)
  File "/home/muzavan/Documents/Proyek/kosong/level/models.py", line 27, in newLevel
    cnx.close()
UnboundLocalError: local variable 'cnx' referenced before assignment
[02/Jul/2015 04:31:56] ERROR [django.request:256] Internal Server Error: /new-level/settings/settings/
Traceback (most recent call last):
  File "/usr/local/lib/python2.7/dist-packages/django/core/handlers/base.py", line 132, in get_response
    response = wrapped_callback(request, *callback_args, **callback_kwargs)
  File "/home/muzavan/Documents/Proyek/kosong/level/views.py", line 22, in newLevel
    util.newLevel(image,answer,hint,name,linkProfile)
  File "/home/muzavan/Documents/Proyek/kosong/level/models.py", line 27, in newLevel
    cnx.close()
UnboundLocalError: local variable 'cnx' referenced before assignment
[02/Jul/2015 04:39:27] DEBUG [django.db.backends:89] (0.000) QUERY = "\n            SELECT name, type FROM sqlite_master\n            WHERE type in ('table', 'view') AND NOT name='sqlite_sequence'\n            ORDER BY name" - PARAMS = (); args=None
[02/Jul/2015 04:39:27] DEBUG [django.db.backends:89] (0.000) QUERY = u'SELECT "django_migrations"."app", "django_migrations"."name" FROM "django_migrations"' - PARAMS = (); args=()
[02/Jul/2015 04:39:32] ERROR [django.request:256] Internal Server Error: /new-level/settings/settings/
Traceback (most recent call last):
  File "/usr/local/lib/python2.7/dist-packages/django/core/handlers/base.py", line 132, in get_response
    response = wrapped_callback(request, *callback_args, **callback_kwargs)
  File "/home/muzavan/Documents/Proyek/kosong/level/views.py", line 22, in newLevel
    util.newLevel(image,answer,hint,name,linkProfile)
  File "/home/muzavan/Documents/Proyek/kosong/level/models.py", line 27, in newLevel
    cnx.close()
UnboundLocalError: local variable 'cnx' referenced before assignment
[02/Jul/2015 04:46:10] DEBUG [django.db.backends:89] (0.001) QUERY = "\n            SELECT name, type FROM sqlite_master\n            WHERE type in ('table', 'view') AND NOT name='sqlite_sequence'\n            ORDER BY name" - PARAMS = (); args=None
[02/Jul/2015 04:46:10] DEBUG [django.db.backends:89] (0.000) QUERY = u'SELECT "django_migrations"."app", "django_migrations"."name" FROM "django_migrations"' - PARAMS = (); args=()
[02/Jul/2015 04:46:16] ERROR [django.request:256] Internal Server Error: /new-level/settings/settings/
Traceback (most recent call last):
  File "/usr/local/lib/python2.7/dist-packages/django/core/handlers/base.py", line 132, in get_response
    response = wrapped_callback(request, *callback_args, **callback_kwargs)
  File "/home/muzavan/Documents/Proyek/kosong/level/views.py", line 22, in newLevel
    util.newLevel(image,answer,hint,name,linkProfile)
  File "/home/muzavan/Documents/Proyek/kosong/level/models.py", line 27, in newLevel
    cnx.close()
UnboundLocalError: local variable 'cnx' referenced before assignment
[02/Jul/2015 04:52:29] DEBUG [django.db.backends:89] (0.000) QUERY = "\n            SELECT name, type FROM sqlite_master\n            WHERE type in ('table', 'view') AND NOT name='sqlite_sequence'\n            ORDER BY name" - PARAMS = (); args=None
[02/Jul/2015 04:52:29] DEBUG [django.db.backends:89] (0.000) QUERY = u'SELECT "django_migrations"."app", "django_migrations"."name" FROM "django_migrations"' - PARAMS = (); args=()
[02/Jul/2015 04:52:35] ERROR [django.request:256] Internal Server Error: /new-level/settings/settings/
Traceback (most recent call last):
  File "/usr/local/lib/python2.7/dist-packages/django/core/handlers/base.py", line 132, in get_response
    response = wrapped_callback(request, *callback_args, **callback_kwargs)
  File "/home/muzavan/Documents/Proyek/kosong/level/views.py", line 23, in newLevel
    return HttpResponse("Sudah Disimpan")
NameError: global name 'HttpResponse' is not defined
[02/Jul/2015 04:59:11] DEBUG [django.db.backends:89] (0.000) QUERY = "\n            SELECT name, type FROM sqlite_master\n            WHERE type in ('table', 'view') AND NOT name='sqlite_sequence'\n            ORDER BY name" - PARAMS = (); args=None
[02/Jul/2015 04:59:11] DEBUG [django.db.backends:89] (0.000) QUERY = u'SELECT "django_migrations"."app", "django_migrations"."name" FROM "django_migrations"' - PARAMS = (); args=()
[02/Jul/2015 05:10:59] DEBUG [django.db.backends:89] (0.000) QUERY = "\n            SELECT name, type FROM sqlite_master\n            WHERE type in ('table', 'view') AND NOT name='sqlite_sequence'\n            ORDER BY name" - PARAMS = (); args=None
[02/Jul/2015 05:10:59] DEBUG [django.db.backends:89] (0.000) QUERY = u'SELECT "django_migrations"."app", "django_migrations"."name" FROM "django_migrations"' - PARAMS = (); args=()
[02/Jul/2015 05:14:45] DEBUG [django.db.backends:89] (0.000) QUERY = "\n            SELECT name, type FROM sqlite_master\n            WHERE type in ('table', 'view') AND NOT name='sqlite_sequence'\n            ORDER BY name" - PARAMS = (); args=None
[02/Jul/2015 05:14:45] DEBUG [django.db.backends:89] (0.000) QUERY = u'SELECT "django_migrations"."app", "django_migrations"."name" FROM "django_migrations"' - PARAMS = (); args=()
[02/Jul/2015 05:17:20] DEBUG [django.db.backends:89] (0.000) QUERY = "\n            SELECT name, type FROM sqlite_master\n            WHERE type in ('table', 'view') AND NOT name='sqlite_sequence'\n            ORDER BY name" - PARAMS = (); args=None
[02/Jul/2015 05:17:20] DEBUG [django.db.backends:89] (0.000) QUERY = u'SELECT "django_migrations"."app", "django_migrations"."name" FROM "django_migrations"' - PARAMS = (); args=()
[02/Jul/2015 05:17:47] DEBUG [django.db.backends:89] (0.000) QUERY = "\n            SELECT name, type FROM sqlite_master\n            WHERE type in ('table', 'view') AND NOT name='sqlite_sequence'\n            ORDER BY name" - PARAMS = (); args=None
[02/Jul/2015 05:17:47] DEBUG [django.db.backends:89] (0.000) QUERY = u'SELECT "django_migrations"."app", "django_migrations"."name" FROM "django_migrations"' - PARAMS = (); args=()
[02/Jul/2015 05:22:37] DEBUG [django.db.backends:89] (0.000) QUERY = "\n            SELECT name, type FROM sqlite_master\n            WHERE type in ('table', 'view') AND NOT name='sqlite_sequence'\n            ORDER BY name" - PARAMS = (); args=None
[02/Jul/2015 05:22:37] DEBUG [django.db.backends:89] (0.000) QUERY = u'SELECT "django_migrations"."app", "django_migrations"."name" FROM "django_migrations"' - PARAMS = (); args=()
[02/Jul/2015 05:22:50] DEBUG [django.db.backends:89] (0.000) QUERY = "\n            SELECT name, type FROM sqlite_master\n            WHERE type in ('table', 'view') AND NOT name='sqlite_sequence'\n            ORDER BY name" - PARAMS = (); args=None
[02/Jul/2015 05:22:50] DEBUG [django.db.backends:89] (0.000) QUERY = u'SELECT "django_migrations"."app", "django_migrations"."name" FROM "django_migrations"' - PARAMS = (); args=()
[02/Jul/2015 05:22:58] DEBUG [django.db.backends:89] (0.000) QUERY = "\n            SELECT name, type FROM sqlite_master\n            WHERE type in ('table', 'view') AND NOT name='sqlite_sequence'\n            ORDER BY name" - PARAMS = (); args=None
[02/Jul/2015 05:22:58] DEBUG [django.db.backends:89] (0.000) QUERY = u'SELECT "django_migrations"."app", "django_migrations"."name" FROM "django_migrations"' - PARAMS = (); args=()
[02/Jul/2015 05:23:06] DEBUG [django.db.backends:89] (0.000) QUERY = "\n            SELECT name, type FROM sqlite_master\n            WHERE type in ('table', 'view') AND NOT name='sqlite_sequence'\n            ORDER BY name" - PARAMS = (); args=None
[02/Jul/2015 05:23:06] DEBUG [django.db.backends:89] (0.000) QUERY = u'SELECT "django_migrations"."app", "django_migrations"."name" FROM "django_migrations"' - PARAMS = (); args=()
[02/Jul/2015 06:13:47] DEBUG [django.db.backends:89] (0.001) QUERY = "\n            SELECT name, type FROM sqlite_master\n            WHERE type in ('table', 'view') AND NOT name='sqlite_sequence'\n            ORDER BY name" - PARAMS = (); args=None
[02/Jul/2015 06:13:47] DEBUG [django.db.backends:89] (0.000) QUERY = u'SELECT "django_migrations"."app", "django_migrations"."name" FROM "django_migrations"' - PARAMS = (); args=()
[02/Jul/2015 06:26:59] ERROR [django.request:256] Internal Server Error: /new-level/
Traceback (most recent call last):
  File "/usr/local/lib/python2.7/dist-packages/django/core/handlers/base.py", line 119, in get_response
    resolver_match = resolver.resolve(request.path_info)
  File "/usr/local/lib/python2.7/dist-packages/django/core/urlresolvers.py", line 368, in resolve
    sub_match = pattern.resolve(new_path)
  File "/usr/local/lib/python2.7/dist-packages/django/core/urlresolvers.py", line 240, in resolve
    return ResolverMatch(self.callback, args, kwargs, self.name)
  File "/usr/local/lib/python2.7/dist-packages/django/core/urlresolvers.py", line 247, in callback
    self._callback = get_callable(self._callback_str)
  File "/usr/local/lib/python2.7/dist-packages/django/utils/lru_cache.py", line 101, in wrapper
    result = user_function(*args, **kwds)
  File "/usr/local/lib/python2.7/dist-packages/django/core/urlresolvers.py", line 106, in get_callable
    mod = import_module(mod_name)
  File "/usr/lib/python2.7/importlib/__init__.py", line 37, in import_module
    __import__(name)
  File "/home/muzavan/Documents/Proyek/kosong/level/views.py", line 33
    with open(media+"/"+name, 'wb+') as destination:
    ^
IndentationError: unexpected indent
[02/Jul/2015 06:28:49] ERROR [django.request:256] Internal Server Error: /new-level/
Traceback (most recent call last):
  File "/usr/local/lib/python2.7/dist-packages/django/core/handlers/base.py", line 119, in get_response
    resolver_match = resolver.resolve(request.path_info)
  File "/usr/local/lib/python2.7/dist-packages/django/core/urlresolvers.py", line 368, in resolve
    sub_match = pattern.resolve(new_path)
  File "/usr/local/lib/python2.7/dist-packages/django/core/urlresolvers.py", line 240, in resolve
    return ResolverMatch(self.callback, args, kwargs, self.name)
  File "/usr/local/lib/python2.7/dist-packages/django/core/urlresolvers.py", line 247, in callback
    self._callback = get_callable(self._callback_str)
  File "/usr/local/lib/python2.7/dist-packages/django/utils/lru_cache.py", line 101, in wrapper
    result = user_function(*args, **kwds)
  File "/usr/local/lib/python2.7/dist-packages/django/core/urlresolvers.py", line 106, in get_callable
    mod = import_module(mod_name)
  File "/usr/lib/python2.7/importlib/__init__.py", line 37, in import_module
    __import__(name)
  File "/home/muzavan/Documents/Proyek/kosong/level/views.py", line 34
    for chunk in f.chunks():
      ^
IndentationError: expected an indented block
